2025-02-25 07:51:22.330690: E external/local_xla/xla/stream_executor/cuda/cuda_fft.cc:477] Unable to register cuFFT factory: Attempting to register factory for plugin cuFFT when one has already been registered
WARNING: All log messages before absl::InitializeLog() is called are written to STDERR
E0000 00:00:1740469882.352195    7772 cuda_dnn.cc:8310] Unable to register cuDNN factory: Attempting to register factory for plugin cuDNN when one has already been registered
E0000 00:00:1740469882.358793    7772 cuda_blas.cc:1418] Unable to register cuBLAS factory: Attempting to register factory for plugin cuBLAS when one has already been registered
Global seed set to 1501
GPU available: True (cuda), used: True
TPU available: False, using: 0 TPU cores
IPU available: False, using: 0 IPUs
HPU available: False, using: 0 HPUs
Missing logger folder: /content/drive/MyDrive/projects/emg2qwerty-main/logs/2025-02-25/07-51-17/job0_trainer.devices=1,user=single_user/lightning_logs
LOCAL_RANK: 0 - CUDA_VISIBLE_DEVICES: [0]
/usr/local/lib/python3.11/dist-packages/pl_bolts/__init__.py:11: FutureWarning: In the future `np.object` will be defined as the corresponding NumPy scalar.
  if not hasattr(numpy, tp_name):
/usr/local/lib/python3.11/dist-packages/pl_bolts/__init__.py:11: FutureWarning: In the future `np.bool` will be defined as the corresponding NumPy scalar.
  if not hasattr(numpy, tp_name):
/usr/local/lib/python3.11/dist-packages/pl_bolts/models/self_supervised/amdim/amdim_module.py:34: UnderReviewWarning: The feature generate_power_seq is currently marked under review. The compatibility with other Lightning projects is not guaranteed and API may change at any time. The API and functionality may change without warning in future releases. More details: https://lightning-bolts.readthedocs.io/en/latest/stability.html
  "lr_options": generate_power_seq(LEARNING_RATE_CIFAR, 11),
/usr/local/lib/python3.11/dist-packages/pl_bolts/models/self_supervised/amdim/amdim_module.py:92: UnderReviewWarning: The feature FeatureMapContrastiveTask is currently marked under review. The compatibility with other Lightning projects is not guaranteed and API may change at any time. The API and functionality may change without warning in future releases. More details: https://lightning-bolts.readthedocs.io/en/latest/stability.html
  contrastive_task: Union[FeatureMapContrastiveTask] = FeatureMapContrastiveTask("01, 02, 11"),
/usr/local/lib/python3.11/dist-packages/pl_bolts/losses/self_supervised_learning.py:228: UnderReviewWarning: The feature AmdimNCELoss is currently marked under review. The compatibility with other Lightning projects is not guaranteed and API may change at any time. The API and functionality may change without warning in future releases. More details: https://lightning-bolts.readthedocs.io/en/latest/stability.html
  self.nce_loss = AmdimNCELoss(tclip)
/usr/local/lib/python3.11/dist-packages/hydra/_internal/instantiate/_instantiate2.py:92: UnderReviewWarning: The feature LinearWarmupCosineAnnealingLR is currently marked under review. The compatibility with other Lightning projects is not guaranteed and API may change at any time. The API and functionality may change without warning in future releases. More details: https://lightning-bolts.readthedocs.io/en/latest/stability.html
  return _target_(*args, **kwargs)

  | Name     | Type       | Params
----------------------------------------
0 | model    | Sequential | 5.3 M 
1 | ctc_loss | CTCLoss    | 0     
2 | metrics  | ModuleDict | 0     
----------------------------------------
5.3 M     Trainable params
0         Non-trainable params
5.3 M     Total params
21.173    Total estimated model params size (MB)
/usr/local/lib/python3.11/dist-packages/torch/utils/data/dataloader.py:558: UserWarning: This DataLoader will create 4 worker processes in total. Our suggested max number of worker in current system is 2, which is smaller than what this DataLoader is going to create. Please be aware that excessive worker creation might get DataLoader running slow or even freeze, lower the worker number to avoid potential slowness/freeze if necessary.
  warnings.warn(_create_warning_msg(
/usr/local/lib/python3.11/dist-packages/torch/nn/modules/conv.py:456: UserWarning: Plan failed with a cudnnException: CUDNN_BACKEND_EXECUTION_PLAN_DESCRIPTOR: cudnnFinalize Descriptor Failed cudnn_status: CUDNN_STATUS_NOT_SUPPORTED (Triggered internally at ../aten/src/ATen/native/cudnn/Conv_v8.cpp:919.)
  return F.conv2d(input, weight, bias, self.stride,
Epoch 0, global step 120: 'val/CER' reached 1358.08594 (best 1358.08594), saving model to '/content/drive/MyDrive/projects/emg2qwerty-main/logs/2025-02-25/07-51-17/job0_trainer.devices=1,user=single_user/checkpoints/epoch=0-step=120.ckpt' as top 1
/usr/local/lib/python3.11/dist-packages/pytorch_lightning/trainer/call.py:48: UserWarning: Detected KeyboardInterrupt, attempting graceful shutdown...
  rank_zero_warn("Detected KeyboardInterrupt, attempting graceful shutdown...")
Exception in thread Thread-4 (_pin_memory_loop):
Traceback (most recent call last):
  File "/usr/lib/python3.11/threading.py", line 1045, in _bootstrap_inner
    self.run()
  File "/usr/lib/python3.11/threading.py", line 982, in run
    self._target(*self._args, **self._kwargs)
  File "/usr/local/lib/python3.11/dist-packages/torch/utils/data/_utils/pin_memory.py", line 54, in _pin_memory_loop
    do_one_step()
  File "/usr/local/lib/python3.11/dist-packages/torch/utils/data/_utils/pin_memory.py", line 31, in do_one_step
    r = in_queue.get(timeout=MP_STATUS_CHECK_INTERVAL)
        ^^^^^^^^^^^^^^^^^^^^^^^^^^^^^^^^^^^^^^^^^^^^^^
  File "/usr/lib/python3.11/multiprocessing/queues.py", line 122, in get
    return _ForkingPickler.loads(res)
           ^^^^^^^^^^^^^^^^^^^^^^^^^^
  File "/usr/local/lib/python3.11/dist-packages/torch/multiprocessing/reductions.py", line 495, in rebuild_storage_fd
    fd = df.detach()
         ^^^^^^^^^^^
  File "/usr/lib/python3.11/multiprocessing/resource_sharer.py", line 57, in detach
    with _resource_sharer.get_connection(self._id) as conn:
         ^^^^^^^^^^^^^^^^^^^^^^^^^^^^^^^^^^^^^^^^^
  File "/usr/lib/python3.11/multiprocessing/resource_sharer.py", line 86, in get_connection
    c = Client(address, authkey=process.current_process().authkey)
        ^^^^^^^^^^^^^^^^^^^^^^^^^^^^^^^^^^^^^^^^^^^^^^^^^^^^^^^^^^
  File "/usr/lib/python3.11/multiprocessing/connection.py", line 519, in Client
    c = SocketClient(address)
        ^^^^^^^^^^^^^^^^^^^^^
  File "/usr/lib/python3.11/multiprocessing/connection.py", line 647, in SocketClient
    s.connect(address)
FileNotFoundError: [Errno 2] No such file or directory
